<?xml version='1.0' encoding='UTF-8'?>
<mujoco>

    <option timestep="0.001"/>
    <option gravity="0 0 0"/>

    <asset>
        <texture type="skybox" builtin="gradient" rgb1="1 1 1" rgb2="0.5 0.5 0.8" width="265" height="256"/>
        <texture name="grid" type="2d" builtin="checker" rgb1="0.1 0.1 0.1" rgb2="0.6 0.6 0.8" width="300" height="300"/>
        <material name="grid" texture="grid" texrepeat="10 10" reflectance="0.2"/>
    </asset>

    <worldbody>
        <light pos="0 0 10"/>
        <geom type="plane" size="0.5 0.5 0.1" material="grid"/>
        
        <body name="ABC" pos="0 0 0" euler="0 0 0">
            <joint name="joint A" type="hinge" axis="0 0 1" limited="true" range="-180 180" />
            <geom name="point A" type="cylinder" pos="0 0 0.02" size="0.02 0.02" rgba="0.89 0.14 0.16 0.8"/>
            <geom name="link A" type="cylinder" pos="0 0 0.12" size="0.02 0.1" rgba="0.89 0.14 0.16 0.8" euler="0 0 0"/>

            <body name="BC" pos="0 0 0.24" euler="90 0 0">
                <joint name="joint B" type="hinge" axis="0 0 1" limited="true" range="-180 180" />
                <geom name="point B" type="cylinder" pos="0 0 0" size="0.02 0.02" rgba="0.89 0.14 0.16 0.8" euler="0 0 0" contype="0"/>
                <geom name="link B" type="cylinder" pos="0.1 0 0" size="0.02 0.1" rgba="0.14 0.89 0.16 0.8" euler="0 90 0"/>

                <body name="C" pos="0.21 0 0" euler="0 0 0">
                    <joint name="joint C" type="hinge" axis="0 0 1" limited="true" range="-180 180" />
                    <geom name="point C" type="cylinder" pos="0 0 0" size="0.02 0.02" rgba="0.89 0.14 0.16 0.8" euler="0 0 0" contype="0"/>
                    <geom name="link C" type="cylinder" pos="0.1 0 0" size="0.02 0.1" rgba="0.14 0.16 0.89 0.8" euler="0 90 0"/>
                    <site name="sP" size="0.01" pos="0.2 0 0"/>
                </body>

            </body>

        </body>
            
    </worldbody>




    <actuator>
        <position name="joint A" joint="joint A" kp="5" dampratio="1" ctrllimited="true" ctrlrange="-3.14 3.14"/>
        <position name="joint B" joint="joint B" kp="5" dampratio="1" ctrllimited="true" ctrlrange="-3.14 3.14"/>
        <position name="joint C" joint="joint C" kp="5" dampratio="0.5" ctrllimited="true" ctrlrange="-3.14 3.14"/>
    </actuator>




    <sensor>
        <framepos objtype="site" objname="sP"/>
    </sensor>


</mujoco>
