<?xml version='1.0' encoding='UTF-8'?>
<mujoco>

    <option timestep="0.001"/>
    <option gravity="0 0 0"/>

    <asset>
        <texture type="skybox" builtin="gradient" rgb1="1 1 1" rgb2="0.5 0.5 0.8" width="265" height="256"/>
        <texture name="grid" type="2d" builtin="checker" rgb1="0.1 0.1 0.1" rgb2="0.6 0.6 0.8" width="300" height="300"/>
        <material name="grid" texture="grid" texrepeat="10 10" reflectance="0.2"/>
    </asset>

    <worldbody>
        <light pos="0 0 10"/>
        <geom type="plane" size="0.5 0.5 0.1" material="grid"/>
        
        <body name="ABCDEF" pos="0 0 0" euler="0 0 0">
            <joint name="joint A" type="hinge" axis="0 0 1" limited="true" range="-180 180" />
            <geom name="point A" type="cylinder" pos="0 0 0.02" size="0.015 0.015" rgba="0.89 0.14 0.16 0.9"/>
            <geom name="link A" type="cylinder" pos="0 0 0.12" size="0.015 0.1" rgba="0.80 0.11 0.51 0.9" euler="0 0 0"/>

            <body name="BCDEF" pos="0 0 0.23" euler="90 0 0">
                <joint name="joint B" type="hinge" axis="0 0 1" limited="true" range="-180 180" />
                <geom name="point B" type="cylinder" pos="0 0 0" size="0.015 0.015" rgba="0.89 0.14 0.16 0.9" euler="0 0 0" contype="0"/>
                <geom name="link B" type="cylinder" pos="0.06 0 0" size="0.015 0.06" rgba="0.14 0.89 0.16 0.9" euler="0 90 0"/>

                <body name="CDEF" pos="0.13 0 0" euler="0 0 0">
                    <joint name="joint C" type="hinge" axis="0 0 1" limited="true" range="-180 180" />
                    <geom name="point C" type="cylinder" pos="0 0 0" size="0.015 0.015" rgba="0.89 0.14 0.16 0.9" euler="0 0 0" contype="0"/>
                    <geom name="link C" type="cylinder" pos="0.06 0 0" size="0.015 0.06" rgba="0.14 0.16 0.89 0.9" euler="0 90 0"/>


                    <body name="DEF" pos="0.13 0 0" euler="0 90 0">
                        <joint name="joint D" type="hinge" axis="0 0 1" limited="true" range="-180 180" />
                        <geom name="point D" type="cylinder" pos="0 0 0" size="0.015 0.015" rgba="0.89 0.14 0.16 0.9" euler="0 0 0" contype="0"/>
                        <geom name="link D" type="cylinder" pos="0 0 0.04" size="0.015 0.04" rgba="0.988 0.73 0.11 0.9" euler="0 0 0"/>


                        <body name="EF" pos="0 0 0.087" euler="0 -90 0">
                            <joint name="joint E" type="hinge" axis="0 0 1" limited="true" range="-180 180" />
                            <geom name="point E" type="cylinder" pos="0 0 0" size="0.015 0.015" rgba="0.89 0.14 0.16 0.9" euler="0 0 0" contype="0"/>
                            <geom name="link E" type="cylinder" pos="0.04 0 0" size="0.015 0.04" rgba="0.80 0.11 0.89 0.9" euler="0 90 0"/>


                            <body name="F" pos="0.087 0 0" euler="0 90 0">
                                <joint name="joint F" type="hinge" axis="0 0 1" limited="true" range="-180 180" />
                                <geom name="point F" type="cylinder" pos="0 0 0" size="0.015 0.015" rgba="0.89 0.14 0.16 0.9" euler="0 0 0" contype="0"/>
                                <geom name="link F" type="cylinder" pos="0 0 0.04" size="0.015 0.04" rgba="0.11 0.8 0.8 0.9" euler="0 0 0"/>
                                <site name="sP" size="0.01" pos="0 0 0.08"/>
                            </body>


                        </body>

                    </body>

                </body>

            </body>

        </body>
            
    </worldbody>




    <actuator>
        <position name="joint A" joint="joint A" kp="5" dampratio="1" ctrllimited="true" ctrlrange="-3.14 3.14"/>
        <position name="joint B" joint="joint B" kp="5" dampratio="1" ctrllimited="true" ctrlrange="-3.14 3.14"/>
        <position name="joint C" joint="joint C" kp="5" dampratio="0.5" ctrllimited="true" ctrlrange="-3.14 3.14"/>
    </actuator>




    <sensor>
        <framepos objtype="site" objname="sP"/>
    </sensor>


</mujoco>
